{
  "errors": [
    {
      "test": "unittest.loader._FailedTest.unit_tests",
      "traceback": "Traceback (most recent call last):\n  File \"c:\\users\\yashas\\anaconda3\\lib\\unittest\\case.py\", line 60, in testPartExecutor\n    yield\n  File \"c:\\users\\yashas\\anaconda3\\lib\\unittest\\case.py\", line 676, in run\n    self._callTestMethod(testMethod)\n  File \"c:\\users\\yashas\\anaconda3\\lib\\unittest\\case.py\", line 633, in _callTestMethod\n    method()\n  File \"c:\\users\\yashas\\anaconda3\\lib\\unittest\\loader.py\", line 34, in testFailure\n    raise self._exception\nImportError: Failed to import test module: unit_tests\nTraceback (most recent call last):\n  File \"c:\\users\\yashas\\anaconda3\\lib\\unittest\\loader.py\", line 154, in loadTestsFromName\n    module = __import__(module_name)\n  File \"c:\\users\\yashas\\desktop\\buy_with_time\\build-tool\\src\\unittest\\python\\unit_tests.py\", line 1, in <module>\n    from src.main.python.users.models import UserModel\nModuleNotFoundError: No module named 'src'\n\n"
    }
  ],
  "failures": [],
  "tests-run": 1
}